<mujocoinclude>
    <!-- ============================================================== -->
    <!-- ===================== For clearpath husky ==================== -->
    <!-- ============================================================== -->
    <body name="base_footprint" pos="0 0 0.13" childclass="husky">
        <joint type="free" stiffness="0" damping="0" frictionloss="0" armature="0" />

        <body name="base" pos="0 0 0">
            <inertial pos="-0.00065 -0.085 0.062"  mass="46.034" fullinertia="0.6022 1.7386 2.0296 -0.02364 -0.1197 -0.001544"/>
            <geom class="husky_collision" size="0.39496 0.28545 0.051875" pos="0 0 0.175625" type="box"/>
            <geom class="husky_collision" size="0.4937 0.28545 0.061875" pos="0 0 0.061875" type="box"/>
            <geom class="husky_visual" pos="0.272 0 0.245" type="mesh" mesh="user_rail" material="black"/>
            <body name="top_structure">
                <geom class="husky_visual" pos="0 0 0" type="mesh" mesh="top_structure" material="black"/>
                <geom class="husky_collision" size="0.19496 0.28 0.65" pos="-0.2 0 0.85" type="box"/>
                <inertial pos="-0.2 0 0.45" mass="40" fullinertia="1.95397859e-01 1.92679403e-01 1.01958752e-01 7.23330468e-08 2.01114568e-02 -7.81325404e-05" />
            </body>
            <geom class="husky_visual" pos="-0.48 0 0.091" quat="0 0 1 0" type="mesh" mesh="bumper" rgba="0.2 0.2 0.2 1.0"/>
            <!-- <geom class="husky_visual" pos="0.48 0 0.091" type="mesh" mesh="bumper" rgba="0.2 0.2 0.2 1.0"/> -->
            <geom class="husky_visual" pos="0 0 0" type="mesh" mesh="base_link" rgba="0.8 0.8 0.0 1.0"/>
            <geom class="husky_visual" pos="0 0 0" type="mesh" mesh="top_chassis" rgba="0.8 0.8 0.0 1.0"/>
            <site name="husky_site"  size = "0.005" rgba = ".1 .1 .9 1" type = "sphere" />

            <body name="front_right_wheel" pos="0.256 -0.2854 0.03282">
                <inertial pos="0 0 0" quat="0.707107 0 0 0.707107" mass="2.637" diaginertia="0.04411 0.02467 0.02467"/>
                <joint name="front_right_wheel" type="hinge" pos="0 0 0" axis="0 1 0"/>
                <geom class="husky_visual" pos="0 0 0" quat="0 0 0 1" mesh="wheel" material="black"/>
                <geom class="husky_collision" size="0.1651 0.05715" quat="0.707107 0.707106 0 0" type="cylinder"/>
            </body>

            <body name="front_left_wheel" pos="0.256 0.2854 0.03282">
                <inertial pos="0 0 0" quat="0.707107 0 0 0.707107" mass="2.637" diaginertia="0.04411 0.02467 0.02467"/>
                <joint name="front_left_wheel" type="hinge" pos="0 0 0" axis="0 1 0"/>
                <geom class="husky_visual" pos="0 0 0" quat="0 0 0 1" mesh="wheel" material="black"/>
                <geom class="husky_collision" size="0.1651 0.05715" quat="0.707107 0.707106 0 0" type="cylinder"/>
            </body>

            <body name="rear_right_wheel" pos="-0.256 -0.2854 0.03282">
                <inertial pos="0 0 0" quat="0.707107 0 0 0.707107" mass="2.637" diaginertia="0.04411 0.02467 0.02467"/>
                <joint name="rear_right_wheel" type="hinge" pos="0 0 0" axis="0 1 0" />
                <geom class="husky_visual" pos="0 0 0" quat="0 0 0 1" mesh="wheel" material="black"/>
                <geom class="husky_collision" size="0.1651 0.05715" quat="0.707107 0.707106 0 0" type="cylinder"/>
            </body>

            <body name="rear_left_wheel" pos="-0.256 0.2854 0.03282">
                <inertial pos="0 0 0" quat="0.707107 0 0 0.707107" mass="2.637" diaginertia="0.04411 0.02467 0.02467"/>
                <joint name="rear_left_wheel" type="hinge" pos="0 0 0" axis="0 1 0"/>
                <geom class="husky_visual" pos="0 0 0" quat="0 0 0 1" mesh="wheel" material="black"/>
                <geom class="husky_collision" size="0.1651 0.05715" quat="0.707107 0.707106 0 0" type="cylinder"/>
            </body>

            <!-- ============================================================== -->
            <!-- ====================== For franka panda ====================== -->
            <!-- ============================================================== -->
            <light name="top" pos="0 0 2" mode="trackcom"/>
            <!--============================ link0 ============================ -->
            <body name="link0" childclass="panda" pos="0.3 0 0.256">
                <inertial mass="0.629769" pos="-0.041018 -0.00014 0.049974"
                    fullinertia="0.00315 0.00388 0.004285 8.2904e-7 0.00015 8.2299e-6"/>
                <geom mesh="link0_0" material="off_white" class="panda_visual"/>
                <geom mesh="link0_1" material="black" class="panda_visual"/>
                <geom mesh="link0_2" material="off_white" class="panda_visual"/>
                <geom mesh="link0_3" material="black" class="panda_visual"/>
                <geom mesh="link0_4" material="off_white" class="panda_visual"/>
                <geom mesh="link0_5" material="black" class="panda_visual"/>
                <geom mesh="link0_7" material="white" class="panda_visual"/>
                <geom mesh="link0_8" material="white" class="panda_visual"/>
                <geom mesh="link0_9" material="black" class="panda_visual"/>
                <geom mesh="link0_10" material="off_white" class="panda_visual"/>
                <geom mesh="link0_11" material="white" class="panda_visual"/>
                <geom mesh="link0_c" class="panda_collision"/>
                <!--============================ link1 ============================ -->
                <body name="link1" pos="0 0 0.333">
                    <inertial mass="4.970684" pos="0.003875 0.002081 -0.04762"
                    fullinertia="0.70337 0.70661 0.0091170 -0.00013900 0.0067720 0.019169"/>
                    <joint name="joint1"/>
                    <geom material="white" mesh="link1" class="panda_visual"/>
                    <geom mesh="link1_c" class="panda_collision"/>
                    <!--============================ link2 ============================ -->
                    <body name="link2" quat="1 -1 0 0">
                        <inertial mass="0.646926" pos="-0.003141 -0.02872 0.003495"
                            fullinertia="0.0079620 2.8110e-2 2.5995e-2 -3.925e-3 1.0254e-2 7.04e-4"/>
                        <joint name="joint2" range="-1.7628 1.7628"/>
                        <geom material="white" mesh="link2" class="panda_visual"/>
                        <geom mesh="link2_c" class="panda_collision"/>
                        <!--============================ link3 ============================ -->
                        <body name="link3" pos="0 -0.316 0" quat="1 1 0 0">
                            <joint name="joint3"/>
                            <inertial mass="3.228604" pos="2.7518e-2 3.9252e-2 -6.6502e-2"
                            fullinertia="3.7242e-2 3.6155e-2 1.083e-2 -4.761e-3 -1.1396e-2 -1.2805e-2"/>
                            <geom mesh="link3_0" material="white" class="panda_visual"/>
                            <geom mesh="link3_1" material="white" class="panda_visual"/>
                            <geom mesh="link3_2" material="white" class="panda_visual"/>
                            <geom mesh="link3_3" material="black" class="panda_visual"/>
                            <geom mesh="link3_c" class="panda_collision"/>
                            <!--============================ link4 ============================ -->
                            <body name="link4" pos="0.0825 0 0" quat="1 1 0 0">
                                <inertial mass="3.587895" pos="-5.317e-2 1.04419e-1 2.7454e-2"
                                    fullinertia="2.5853e-2 1.9552e-2 2.8323e-2 7.796e-3 -1.332e-3 8.641e-3"/>
                                <joint name="joint4" range="-3.0718 -0.0698"/>
                                <geom mesh="link4_0" material="white" class="panda_visual"/>
                                <geom mesh="link4_1" material="white" class="panda_visual"/>
                                <geom mesh="link4_2" material="black" class="panda_visual"/>
                                <geom mesh="link4_3" material="white" class="panda_visual"/>
                                <geom mesh="link4_c" class="panda_collision"/>
                                <!--============================ link5 ============================ -->
                                <body name="link5" pos="-0.0825 0.384 0" quat="1 -1 0 0">
                                    <inertial mass="1.225946" pos="-1.1953e-2 4.1065e-2 -3.8437e-2"
                                    fullinertia="3.5549e-2 2.9474e-2 8.627e-3 -2.117e-3 -4.037e-3 2.29e-4"/>
                                    <joint name="joint5"/>
                                    <geom mesh="link5_0" material="black" class="panda_visual"/>
                                    <geom mesh="link5_1" material="white" class="panda_visual"/>
                                    <geom mesh="link5_2" material="white" class="panda_visual"/>
                                    <geom mesh="link5_c0" class="panda_collision"/>
                                    <geom mesh="link5_c1" class="panda_collision"/>
                                    <geom mesh="link5_c2" class="panda_collision"/>
                                    <!--============================ link6 ============================ -->
                                    <body name="link6" quat="1 1 0 0">
                                        <inertial mass="1.666555" pos="6.0149e-2 -1.4117e-2 -1.0517e-2"
                                            fullinertia="1.964e-3 4.354e-3 5.433e-3 1.09e-4 -1.158e-3 3.41e-4"/>
                                        <joint name="joint6" range="-0.0175 3.7525"/>
                                        <geom mesh="link6_0" material="off_white" class="panda_visual"/>
                                        <geom mesh="link6_1" material="white" class="panda_visual"/>
                                        <geom mesh="link6_2" material="black" class="panda_visual"/>
                                        <geom mesh="link6_3" material="white" class="panda_visual"/>
                                        <geom mesh="link6_4" material="white" class="panda_visual"/>
                                        <geom mesh="link6_5" material="white" class="panda_visual"/>
                                        <geom mesh="link6_6" material="white" class="panda_visual"/>
                                        <geom mesh="link6_7" material="light_blue" class="panda_visual"/>
                                        <geom mesh="link6_8" material="light_blue" class="panda_visual"/>
                                        <geom mesh="link6_9" material="black" class="panda_visual"/>
                                        <geom mesh="link6_10" material="black" class="panda_visual"/>
                                        <geom mesh="link6_11" material="white" class="panda_visual"/>
                                        <geom mesh="link6_12" material="green" class="panda_visual"/>
                                        <geom mesh="link6_13" material="white" class="panda_visual"/>
                                        <geom mesh="link6_14" material="black" class="panda_visual"/>
                                        <geom mesh="link6_15" material="black" class="panda_visual"/>
                                        <geom mesh="link6_16" material="white" class="panda_visual"/>
                                        <geom mesh="link6_c" class="panda_collision"/>
                                        <!--============================ link7 ============================ -->
                                        <body name="link7" pos="0.088 0 0" quat="1 1 0 0">
                                            <inertial mass="7.35522e-01" pos="1.0517e-2 -4.252e-3 6.1597e-2"
                                            fullinertia="1.2516e-2 1.0027e-2 4.815e-3 -4.28e-4 -1.196e-3 -7.41e-4"/>
                                            <joint name="joint7"/>
                                            <geom mesh="link7_0" material="white" class="panda_visual"/>
                                            <geom mesh="link7_1" material="black" class="panda_visual"/>
                                            <geom mesh="link7_2" material="black" class="panda_visual"/>
                                            <geom mesh="link7_3" material="black" class="panda_visual"/>
                                            <geom mesh="link7_4" material="black" class="panda_visual"/>
                                            <geom mesh="link7_5" material="black" class="panda_visual"/>
                                            <geom mesh="link7_6" material="black" class="panda_visual"/>
                                            <geom mesh="link7_7" material="white" class="panda_visual"/>
                                            <geom mesh="link7_c" class="panda_collision"/>
                                            <!--============================ hand ============================ -->
                                            <body name="hand" pos="0 0 0.107" quat="0.9238795 0 0 -0.3826834">
                                                <inertial mass="0.73" pos="-0.01 0 0.03" diaginertia="0.001 0.0025 0.0017"/>
                                                <geom mesh="hand_0" material="off_white" class="panda_visual"/>
                                                <geom mesh="hand_1" material="black" class="panda_visual"/>
                                                <geom mesh="hand_2" material="black" class="panda_visual"/>
                                                <geom mesh="hand_3" material="white" class="panda_visual"/>
                                                <geom mesh="hand_4" material="off_white" class="panda_visual"/>
                                                <geom mesh="hand_c" class="panda_collision"/>
                                                <!--============================ left finger ============================ -->
                                                <body name="left_finger" pos="0 0 0.0584">
                                                    <inertial mass="0.015" pos="0 0 0" diaginertia="2.375e-6 2.375e-6 7.5e-7"/>
                                                    <joint name="finger_joint1" class="finger"/>
                                                    <geom mesh="finger_0" material="off_white" class="panda_visual"/>
                                                    <geom mesh="finger_1" material="black" class="panda_visual"/>
                                                    <geom mesh="finger_0" class="panda_collision"/>
                                                    <geom class="fingertip_pad_collision_1"/>
                                                    <geom class="fingertip_pad_collision_2"/>
                                                    <geom class="fingertip_pad_collision_3"/>
                                                    <geom class="fingertip_pad_collision_4"/>
                                                    <geom class="fingertip_pad_collision_5"/>
                                                </body>
                                                <!--============================ right finger ============================ -->
                                                <body name="right_finger" pos="0 0 0.0584" quat="0 0 0 1">
                                                    <inertial mass="0.015" pos="0 0 0" diaginertia="2.375e-6 2.375e-6 7.5e-7"/>
                                                    <joint name="finger_joint2" class="finger"/>
                                                    <geom mesh="finger_0" material="off_white" class="panda_visual"/>
                                                    <geom mesh="finger_1" material="black" class="panda_visual"/>
                                                    <geom mesh="finger_0" class="panda_collision"/>
                                                    <geom class="fingertip_pad_collision_1"/>
                                                    <geom class="fingertip_pad_collision_2"/>
                                                    <geom class="fingertip_pad_collision_3"/>
                                                    <geom class="fingertip_pad_collision_4"/>
                                                    <geom class="fingertip_pad_collision_5"/>
                                                </body>
                                            </body>
                                        </body>
                                    </body>
                                </body>
                            </body>
                        </body>
                    </body>
                </body>
            </body>
        </body>
    </body>
</mujocoinclude>